{\rtf1\ansi\ansicpg1252\cocoartf1504\cocoasubrtf830
{\fonttbl\f0\fnil\fcharset0 Menlo-Regular;}
{\colortbl;\red255\green255\blue255;\red0\green0\blue0;\red255\green255\blue255;}
{\*\expandedcolortbl;;\csgray\c0;\csgray\c100000;}
\paperw11900\paperh16840\margl1440\margr1440\vieww10800\viewh8400\viewkind0
\pard\tx560\tx1120\tx1680\tx2240\tx2800\tx3360\tx3920\tx4480\tx5040\tx5600\tx6160\tx6720\pardirnatural\partightenfactor0

\f0\fs22 \cf2 \cb3 \CocoaLigature0 [root@VM_195_208_centos wujiangang]# python manage.py profile  \
 * Running on https://0.0.0.0:80/ (Press CTRL+C to quit)\
 * Restarting with stat\
 * Debugger is active!\
 * Debugger pin code: 696-810-675\
Exception in thread Thread-1:\
Traceback (most recent call last):\
  File "/root/anaconda3/lib/python3.6/threading.py", line 916, in _bootstrap_inner\
    self.run()\
  File "/root/anaconda3/lib/python3.6/threading.py", line 864, in run\
    self._target(*self._args, **self._kwargs)\
  File "/root/anaconda3/lib/python3.6/site-packages/werkzeug/serving.py", line 670, in inner\
    fd=fd)\
  File "/root/anaconda3/lib/python3.6/site-packages/werkzeug/serving.py", line 564, in make_server\
    passthrough_errors, ssl_context, fd=fd)\
  File "/root/anaconda3/lib/python3.6/site-packages/werkzeug/serving.py", line 500, in __init__\
    self.socket = ssl_context.wrap_socket(sock, server_side=True)\
  File "/root/anaconda3/lib/python3.6/site-packages/werkzeug/serving.py", line 422, in wrap_socket\
    ssl_version=self._protocol, **kwargs)\
  File "/root/anaconda3/lib/python3.6/ssl.py", line 1142, in wrap_socket\
    ciphers=ciphers)\
  File "/root/anaconda3/lib/python3.6/ssl.py", line 741, in __init__\
    self._context.load_cert_chain(certfile, keyfile)\
FileNotFoundError: [Errno 2] No such file or directory}